Workbook

Sheet Observation
A6: Row Labels | B6: Sum of Accumulated Balance
A7: Assets | B7: 3.2091825e+09 | D7: =BS!F55 -> 2.9976385e+09 | E7: =D7-B7 -> -2.1154393e+08
A8: Liablities | B8: -3.4906291e+09 | C8: =B8+B9 -> -3.2091825e+09 | D8: =BS!F32 -> 2.9976385e+09 | E8: =D8+C8 -> -2.1154393e+08 | F8: =E8-E7 -> -0.46000004
A9: PNL | B9: 2.8144664e+08 | D9: =PL!G33 -> 1.2032169e+08 | E9: =D9+B9 -> 4.0176833e+08
A10: Grand Total | B10: -1.1920929e-07

Sheet BS
A2: Moonstone Realinfra Private Limited
A3: CIN :- U45201PN2022PTC207521
A4: A 102 ICC TRADE TOWER 403/A SENAPATI BAPAT ROAD PUNE , MH 411016
A5: Balance Sheet as at 31.03.2026
A6: Particulars | C6: Note No | D6: HO | F6: Construction Division | H6: Total
D7: =H7 -> Figures as at the end of 31.03.2026 | E7: Figures as at the end of 31.03.2025 | F7: =H7 -> Figures as at the end of 31.03.2026 | G7: Figures as at the end of 31.03.2025 | H7: Figures as at the end of 31.03.2026 | I7: Figures as at the end of 31.03.2025
A9: I. EQUITY AND LIABILITIES
A11: (1) Shareholder's Funds
A12: (a) Share Capital | C12: Note 1A | D12: 0 | E12: 0 | F12: =ESC!C18 -> 100000 | G12: 100000 | H12: =ESC!C18 -> 100000 | I12: =ESC!E18 -> 100000
A13: (b) Reserves and Surplus | C13: Note-1B | D13: =+Notes!B10 -> -30616.78 | E13: =Notes!C10 -> -30616.78 | F13: =Notes!D10 -> 87831217 | G13: =Notes!E10 -> -83426.209 | H13: =Notes!F10 -> 87800601 | I13: =Notes!G10 -> -114042.99
A14: (c) Money Received Against Share Warrants | G14: 0 | H14: =D14+F14 -> 0 | I14: =E14+G14 -> 0
A16: (2) Share Application Money Pending Allotment | E16: =Notes!C23 -> 0 | G16: 0 | H16: =D16+F16 -> 0 | I16: =E16+G16 -> 0
A18: (3) Non-Current Liabilities
A19: (a) Long-Term Borrowings | D19: 0 | E19: 0 | F19: =Notes!F19 -> 3.853325e+08 | G19: =Notes!G19 -> 0 | H19: =Notes!F19 -> 3.853325e+08 | I19: =Notes!G19 -> 0
A20: (b) Deferred Tax Liabilities (Net) | D20: 0 | E20: 0 | F20: 0 | G20: 0 | H20: =D20+F20 -> 0 | I20: =E20+G20 -> 0
A21: (c) Other Long Term Liabilities | D21: 0 | E21: 0 | F21: 0 | G21: 0 | H21: =D21+F21 -> 0 | I21: =E21+G21 -> 0
A22: (d) Long-Term Provision | D22: 0 | E22: 0 | F22: 0 | G22: 0 | H22: =D22+F22 -> 0 | I22: =E22+G22 -> 0
A24: (4) Current Liabilities
A25: (a) Short-Term Borrowings | C25: Note-3 | D25: =Notes!B42 -> 258260000 | E25: =Notes!C42 -> 552110000 | F25: =Notes!D42 -> 4.0433683e+08 | G25: =Notes!E42 -> -15907480 | H25: =Notes!F42 -> 6.6259683e+08 | I25: =Notes!G42 -> 536202520
A26: (b) Trade Payable | C26: Note 4
A27: (i) Total Outstanding Dues of Micro Enterprises and Small Enterprises; and | D27: 0 | E27: 0 | F27: ='Note-4'!F8 -> 16500 | G27: ='Note-4'!F17 -> 543846.53 | H27: ='Note-4'!F8 -> 16500 | I27: ='Note-4'!F17 -> 543846.53
A28: (ii) Total Outstanding Dues of Creditors Other Than Micro Enterprises and Small Enterprises | D28: 0 | E28: 0 | F28: ='Note-4'!F9 -> 3.386677e+08 | G28: ='Note-4'!F18 -> 5.7107583e+08 | H28: ='Note-4'!F9 -> 3.386677e+08 | I28: ='Note-4'!F18 -> 5.7107583e+08
A29: (c) Other Current Liabilities | C29: Note-5 | D29: =+Notes!B61 -> -2.7320444e+08 | E29: =Notes!C61 -> -5.6174239e+08 | F29: =Notes!D61 -> 1.7366311e+09 | G29: =Notes!E61 -> 2287780375 | H29: =Notes!F61 -> 1.4634267e+09 | I29: =Notes!G61 -> 1.726038e+09
A30: (d) Short-Term Provisions | C30: Note-6 | D30: =+Notes!B102 -> 21789349 | E30: =Notes!C102 -> 16919070 | F30: =Notes!D102 -> 44722692 | G30: =Notes!E102 -> 1854156.9 | H30: =Notes!F102 -> 66512041 | I30: =Notes!G102 -> 18773227
G31: 0
B32: Total | D32: =SUM(D12:D30) -> 6814293.4 | E32: =SUM(E12:E30) -> 7256064.1 | F32: =SUM(F12:F30) -> 2.9976385e+09 | G32: =SUM(G12:G30) -> 2.8453633e+09 | H32: =SUM(H12:H30) -> 3.0044528e+09 | I32: =SUM(I12:I30) -> 2.8526194e+09
A34: II. Assets
A36: (1) Non-Current Assets
A37: (a) Property, Plant and Equipment
A38: (i) Property, Plant and Equipment | C38: Note-7 | D38: 0 | E38: 0 | F38: ='Dep & DTA DTL'!M9 -> 17765.345 | G38: ='Dep & DTA DTL'!D9 -> 32341.13 | H38: ='Dep & DTA DTL'!M12 -> 17765.345 | I38: ='Dep & DTA DTL'!D12 -> 32341.13
A39: (ii) Intangible Assets | D39: 0 | E39: 0 | F39: 0 | G39: 0 | H39: =D39+F39 -> 0 | I39: =E39+G39 -> 0
A40: (iii) Capital Work-In-Progress | D40: 0 | E40: 0 | F40: 0 | G40: 0 | H40: =D40+F40 -> 0 | I40: =E40+G40 -> 0
A41: (iv) Intangible Assets Under Development | D41: 0 | E41: 0 | F41: 0 | G41: 0 | H41: =D41+F41 -> 0 | I41: =E41+G41 -> 0
A42: (b) Non- Current Investment | H42: =D42+F42 -> 0 | I42: =E42+G42 -> 0
A43: (c) Deferred Tax Assets (Net) | C43: ='Dep & DTA DTL'!B17 -> Note 8 | D43: 0 | E43: 0 | F43: ='Dep & DTA DTL'!C35+G43 -> 5495.5925 | G43: 3586 | H43: =G43+'Dep & DTA DTL'!C35 -> 5495.5925 | I43: ='Dep & DTA DTL'!C36 -> 3586
A44: (d) Long Term Loans And Advances | H44: =D44+F44 -> 0 | I44: =E44+G44 -> 0
A45: (e) Other Non-Current Assets | H45: =D45+F45 -> 0 | I45: =E45+G45 -> 0
A47: (2) Current Assets
A48: (a) Current Investment | C48: Note-9 | D48: 0 | E48: 0 | F48: =Notes!D111 -> 37338046 | G48: =Notes!E111 -> 1055980 | H48: =Notes!F111 -> 37338046 | I48: =Notes!G111 -> 1055980
A49: (b) Inventories | C49: Note-10 | D49: =Notes!B120 -> 0 | E49: =Notes!C120 -> 0 | F49: =Notes!D120 -> 2.9139761e+09 | G49: =Notes!E120 -> 2.8127656e+09 | H49: =Notes!F120 -> 2.9139761e+09 | I49: =Notes!G120 -> 2.8127656e+09
...

Sheet PL
A2: Moonstone Realinfra Private Limited
A3: CIN :- U45201PN2022PTC207521
A4: A 102 ICC TRADE TOWER 403/A SENAPATI BAPAT ROAD PUNE , MH 411016
A5: Statement of Profit & Loss for the year ended 31.03.2026
A6: Particulars | D6: Note No | E6: HO | G6: Construction Division | I6: Total
E7: =I7 -> Figures as at the end of 31.03.2026 | F7: Figures as at the end of 31.03.2025 | G7: =I7 -> Figures as at the end of 31.03.2026 | H7: Figures as at the end of 31.03.2025 | I7: Figures as at the end of 31.03.2026 | J7: Figures as at the end of 31.03.2025
A9: I. Revenue From Operations | D9: =Notes!A175 -> Note-14 | F9: =Notes!C179 -> 0 | G9: =Notes!D182 -> 3.6329722e+08 | H9: =Notes!E182 -> 534581.34 | I9: =Notes!F182 -> 3.6329722e+08 | J9: =Notes!G182 -> 534581.34
A10: II. Other Income | D10: =Notes!A184 -> Note-15 | F10: =Notes!C193 -> 0 | G10: =Notes!D193 -> 2874429.8 | H10: =Notes!E193 -> 98037.001 | I10: =Notes!F193 -> 2874429.8 | J10: =Notes!G193 -> 98037.001
A12: III. Total Revenue (I +II) | G12: =SUM(G9:G10) -> 3.6617165e+08 | H12: =SUM(H9:H10) -> 632618.34 | I12: =SUM(I9:I10) -> 3.6617165e+08 | J12: =SUM(J9:J10) -> 632618.34
A14: IV. Expenses:
A15: (a) Cost of Construction | D15: =Notes!A195 -> Note-16 | F15: =Notes!C240 -> 5834 | G15: =Notes!D240 -> 2.6738234e+08 | H15: =Notes!E240 -> 9.0679174e+08 | I15: =Notes!F240 -> 2.6738234e+08 | J15: =Notes!G240 -> 9.0679758e+08
A16: (b) Purchase of Stock-in-Trade | G16: 0 | H16: 0 | I16: =E16+G16 -> 0 | J16: =F16+H16 -> 0
A17: (c) Changes in Inventories of Finished Goods, work-In Progress and Stock-in-Trade | D17: =Notes!A242 -> Note-17 | F17: =Notes!C254 -> 0 | G17: =Notes!D254 -> -1.0121044e+08 | H17: =Notes!E254 -> -9.2434364e+08 | I17: =Notes!F254 -> -1.0121044e+08 | J17: =Notes!G254 -> -9.2434364e+08
A18: (d) Employee Benefits Expense | F18: =Notes!C255 -> 0 | G18: =Notes!D255 -> 0 | H18: =Notes!E255 -> 0 | I18: =E18+G18 -> 0 | J18: =F18+H18 -> 0
A19: (e) Finance Cost | D19: =Notes!A256 -> Note-18 | F19: =Notes!C264 -> 0 | G19: =Notes!D264 -> 62874802 | H19: =Notes!E264 -> 16021317 | I19: =Notes!F264 -> 62874802 | J19: =Notes!G264 -> 16021317
A20: (f) Depreciation and Amortization Expense | D20: ='Dep & DTA DTL'!B4 -> Note-7 | F20: =Notes!C265 -> 0 | G20: ='Dep & DTA DTL'!L12 -> 14575.785 | H20: 22469.87 | I20: ='Dep & DTA DTL'!L12 -> 14575.785 | J20: =F20+H20 -> 22469.87
A21: (g) Other Expenses | D21: =Notes!A266 -> Note-19 | F21: =Notes!C297 -> 24782.78 | G21: =Notes!D297 -> 16788678 | H21: =Notes!E297 -> 2224845.1 | I21: =Notes!F297 -> 16788678 | J21: =Notes!G297 -> 2249627.9
A23: IV. Total Expenses | F23: =SUM(F15:F21) -> 30616.78 | G23: =SUM(G15:G21) -> 2.4584996e+08 | H23: =SUM(H15:H21) -> 716740 | I23: =SUM(I15:I21) -> 2.4584996e+08 | J23: =SUM(J15:J21) -> 747356.78
A24: V. Profit Before Exceptional and Extraordinary Items And Tax (III - IV)
F25: =F12-F23 -> -30616.78 | G25: =+G12-G23 -> 1.2032169e+08 | H25: =+H12-H23 -> -84121.659 | I25: =+I12-I23 -> 1.2032169e+08 | J25: =+J12-J23 -> -114738.44
A27: VI. Exceptional Items | F27: 0 | G27: 0 | H27: 0 | I27: =E27+G27 -> 0 | J27: =F27+H27 -> 0
A29: VII. Profit Before Extraordinary Items and Tax (V - VI) | F29: =F25-F27 -> -30616.78 | G29: =G25-G27 -> 1.2032169e+08 | H29: =H25-H27 -> -84121.659 | I29: =I25-I27 -> 1.2032169e+08 | J29: =J25-J27 -> -114738.44
A31: VIII. Extraordinary Items | F31: 0 | G31: 0 | H31: 0 | I31: =E31+G31 -> 0 | J31: =F31+H31 -> 0
A33: IX. Profit Before Tax (VII- VIII) | F33: =F29-F31 -> -30616.78 | G33: =G29-G31 -> 1.2032169e+08 | H33: =H29-H31 -> -84121.659 | I33: =I29-I31 -> 1.2032169e+08 | J33: =J29-J31 -> -114738.44
A35: X. Tax Expense:
A36: (1) Current Tax | F36: 0 | I36: =30532486+1876474 -> 32408960 | J36: =F36+H36 -> 0
A37: (2) Deferred Tax | D37: ='Dep & DTA DTL'!B17 -> Note 8 | F37: 0 | G37: =-'Dep & DTA DTL'!C35 -> -1909.5925 | H37: -3586 | I37: =-'Dep & DTA DTL'!C35 -> -1909.5925 | J37: =F37+H37 -> -3586
A38: (3) Taxation For Earlier Years | F38: 0 | H38: 0 | I38: =E38+G38 -> 0 | J38: =F38+H38 -> 0
A40: XI. Profit (Loss) For The Period From Continuing Operations | F40: =F33-F36-F37-F38 -> -30616.78 | G40: =G33-G36-G37-G38 -> 1.203236e+08 | H40: =H33-H36-H37-H38 -> -80535.659 | I40: =I33-I36-I37-I38 -> 87914644 | J40: =J33-J36-J37-J38 -> -111152.44
A42: XII. Profit/(Loss) From Discontinuing Operations | F42: 0 | H42: 0 | I42: =E42+G42 -> 0 | J42: =F42+H42 -> 0
A43: XIII. Tax Expense Of Discontinuing Operations | F43: 0 | H43: 0 | I43: =E43+G43 -> 0 | J43: =F43+H43 -> 0
A45: XIV. Profit/(Loss) From Discontinuing Operations (After Tax) | F45: 0 | H45: =H42-H43 -> 0 | I45: =E45+G45 -> 0 | J45: =F45+H45 -> 0
A47: XV. Profit (Loss) For The Period | F47: =F40+F45 -> -30616.78 | G47: =G40+G45 -> 1.203236e+08 | H47: =H40+H45 -> -80535.659 | I47: =I40+I45 -> 87914644 | J47: =J40+J45 -> -111152.44
A49: XVI. Earning Per Equity Share:
A50: (1) Basic | E50: =E47/10000 -> 0 | F50: =F47/10000 -> -3.061678 | G50: =G47/10000 -> 12032.36 | H50: =H47/10000 -> -8.0535659 | I50: =I47/10000 -> 8791.4644 | J50: =J47/10000 -> -11.115244
A51: (2) Diluted | E51: =E47/10000 -> 0 | F51: =F47/10000 -> -3.061678 | G51: =G47/10000 -> 12032.36 | H51: =H47/10000 -> -8.0535659 | I51: =I47/10000 -> 8791.4644 | J51: =J47/10000 -> -11.115244
A52: Significant Accounting Policies & Notes on Accounts
A54: As per our report of even date
A55: Bhandari S A A J & Associates | I55: For & on behalf of the Board of
A56: Chartered Accountants | I56: Moonstone Realinfra Pvt. Ltd.
...

Sheet Cashflow
A1: Moonstone Realinfra Pvt Ltd
A2: =[1]Balancesheet!A3 -> CIN :- U45201PN2022PTC207521
A3: CASH FLOW STATEMENT
A4: Sr.No. | B4: Particulars | C4: For the year ended 31.03.2026 | D4: For the year ended 31.03.2025
A5: A | B5: Cash Flow From Operating Activities
B6: Net Profit Before Tax | C6: =PL!I33 -> 1.2032169e+08 | D6: =PL!J33 -> -114738.44
B7: Adjustments For
B8: Depreciation | C8: =PL!I20 -> 14575.785 | D8: =PL!J20 -> 22469.87
B9: Finance Cost | C9: =PL!I19 -> 62874802 | D9: =PL!J19 -> 16021317
B10: Operating Profit Before Working Capital Changes | C10: =SUM(C6:C9) -> 1.8321107e+08 | D10: =SUM(D6:D9) -> 15929048
B12: Adjustments For
B13: (Increase) / Decrease In Trade Receivables | C13: =BS!H50-BS!I50 -> 0 | D13: =BS!I50 -> 0
B14: (Increase) /Decrease In Other Current Assets | C14: =-(BS!H53-BS!I53) -> -10182081 | D14: =-BS!I53 -> -29390081
B15: (Increase) /Decrease In Other Non-Current Assets | C15: =BS!H45-BS!I45 -> 0 | D15: =BS!I45 -> 0
B16: Increase / (Decrease) In Other Long Term Liabilities | C16: =BS!H21-BS!I21 -> 0 | D16: =BS!I21 -> 0
B17: Increase / (Decrease) In Trade Payables | C17: =BS!H27+BS!H28-BS!I27-BS!I28 -> -2.3293548e+08 | D17: 5.1885005e+08
B18: Increase/ (Decrease) In Other Current Liabilities | C18: =BS!H29-BS!I29 -> -2.6261133e+08 | D18: 1.0626831e+09
B19: Increase/ (Decrease) In Long Term Provisions | C19: =BS!H22-BS!I22 -> 0 | D19: =[1]Balancesheet!I21-[1]Balancesheet!J21 -> 0
B20: Increase/ (Decrease) In Short Term Provisions | C20: =BS!H30-BS!I30 -> 47738815 | D20: 767510
B21: (Increase) / Decrease In Inventories | C21: =-(BS!H49-BS!I49) -> -1.0121044e+08 | D21: -9.2434364e+08
B23: Cash Generated From Operations | C23: =C10+SUM(C13:C22) -> -3.7598944e+08 | D23: =D10+SUM(D13:D22) -> 6.4449603e+08
B24: Less: Taxes Paid / (Refund) - Net | C24: =PL!I36+PL!I38 -> 32408960 | D24: =[1]PL!I35 -> 0
B25: Net Cash Inflow / (Outflow) From Operating Activities | C25: =C23-C24 -> -4.083984e+08 | D25: =D23-D24 -> 6.4449603e+08
A27: B | B27: Cash Flow From Investing Activities
B28: (Purchase) / Sale Of Fixed Assets | C28: =SUM(BS!H38:H41)+PL!I20-BS!I38 -> 0 | D28: -54811
B29: (Increase) / Decrease In Short Term Loans & Advances | C29: =-(BS!H52-BS!I52) -> -176615 | D29: -41467
B30: (Increase) / Decrease In Long Term Loans & Advances | C30: =BS!H44-BS!I44 -> 0 | D30: 0
B31: (Increase) / Decrease In Non- Current Investment | C31: =BS!H45-BS!I45 -> 0 | D31: 0
B32: (Increase) / Decrease In Current Investment | C32: =-(BS!H48-BS!I48) -> -36282066 | D32: -1055980
B33: Net Cash Flows From Investing Activities | C33: =SUM(C28:C32) -> -36458681 | D33: =SUM(D28:D32) -> -1152258
A35: C | B35: Cash Flow From Financing Activities
B36: Increase/ (Decrease) In Long-Term Borrowings | C36: =BS!H19-BS!I19 -> 3.853325e+08
B37: Increase/ (Decrease) In Short-Term Borrowings | C37: =(BS!H25-BS!I25) -> 1.2639431e+08 | D37: -649291480
B38: Issue of Shares For Cash | C38: =[1]Balancesheet!F11-[1]Balancesheet!G11 -> 0 | D38: =[1]Balancesheet!G11-[1]Balancesheet!H11 -> 0
B39: Finance Costs Paid | C39: =(C9)*-1 -> -62874802 | D39: =(D9)*-1 -> -16021317
B40: Increase/ (Decrease) In Reserve and Surplus | D40: =([1]Balancesheet!I12-[1]Balancesheet!J12)-[1]PL!I46 -> 0
B41: Net Cash Flows From Financing Activities | C41: =SUM(C36:C40) -> 4.48852e+08 | D41: =SUM(D36:D40) -> -665312797
A43: D | B43: Net Changes In Cash & Cash Equivalents (A+B+C) | C43: =C25+C33+C41 -> 3994922 | D43: =D25+D33+D41 -> -21969021
B44: Cash & Cash Equivalents At The Beginning Of The Year | C44: =BS!I51 -> 6890262 | D44: 28859284
B46: Cash & Cash Equivalents At The End Of The Year | C46: =SUM(C43:C44) -> 10885184 | D46: =SUM(D43:D44) -> 6890262.3
...

Sheet Sheet1 (2)

Sheet WIP Final
A1: Moonstone Realinfra Pvt Ltd
A3: Punawale Land
A4: S.No | B4: Area in hectre as per index II | C4: Area in hectre converted to Sq mt as per index II | D4: Land Consideration | E4: Stamp Duty | F4: Commission | G4: Total Cost of Land | H4: Development expenses | I4: Purchased in FY | J4: Land | K4: Project | N4: Stamp Duty & Registration Expenses - on Land Purch
A5: 32/6 | B5: 0.49 | C5: =+B5*10000 -> 4900 | D5: =88673100 -> 88673100 | E5: =5352923.6 -> 5352923.6 | F5: 0 | G5: =+SUM(D5:F5) -> 94026024 | H5: 273000 | I5: 21-22 | J5: =+G5*$C$145 -> 13261266 | K5: =G5*$C$146 -> 80764758 | N5: Out of Pocket Expences
A6: 31/1,31/1/1A.. | B6: =+(0.28+0.6+0.29+0.28) -> 1.45 | C6: =+B6*10000 -> 14500 | D6: =205595682 -> 205595682 | E6: 14424800 | F6: 0 | G6: =+SUM(D6:F6) -> 220020482 | I6: 22-23 | J6: =+G6*$C$145 -> 31031304 | K6: =G6*$C$146 -> 1.8898918e+08 | N6: Conveyance Expenses
A7: 32/1,32/7, 32/3 | B7: =+(1.65+0.895+1) -> 3.545 | C7: =+B7*10000 -> 35450 | D7: =473340000 -> 473340000 | E7: 33170900 | F7: 0 | G7: =+SUM(D7:F7) -> 506510900 | I7: 22-23 | J7: =+G7*$C$145 -> 71437411 | K7: =G7*$C$146 -> 4.3507349e+08 | N7: PF Employer Contribution
A8: 32/3 | B8: 0.895 | C8: =+B8*10000 -> 8950 | D8: =135000000 -> 135000000 | E8: 9480000 | F8: 0 | G8: =+SUM(D8:F8) -> 144480000 | I8: 22-23 | J8: =+G8*$C$145 -> 20377206 | K8: =G8*$C$146 -> 1.2410279e+08 | N8: EDLI Contribution
A9: 34/2/2/2 | B9: 0.8553 | C9: =+B9*10000 -> 8553 | D9: =225000000 -> 225000000 | E9: =15750000+30000 -> 15780000 | F9: 2500000 | G9: =+SUM(D9:F9) -> 243280000 | H9: 3250257.4 | I9: 23-24 | J9: =+G9*$C$145 -> 34311786 | K9: =G9*$C$146 -> 2.0896821e+08 | N9: PF Admin Charges
A10: 34/2/2/3 | B10: =0.8533+0.002 -> 0.8553 | C10: =+B10*10000 -> 8553 | D10: =225000000 -> 225000000 | E10: =15750000+30000 -> 15780000 | F10: 2500000 | G10: =+SUM(D10:F10) -> 243280000 | H10: 3250257 | I10: 23-24 | J10: =+G10*$C$145 -> 34311786 | K10: =G10*$C$146 -> 2.0896821e+08 | N10: Other Deduction related to Personnel Cost
A11: Total area Purchase in Co | B11: =SUM(B5:B10) -> 8.0906 | C11: =SUBTOTAL(9,C5:C10) -> 80906 | D11: =SUBTOTAL(9,D5:D10) -> 1352608782 | E11: =SUBTOTAL(9,E5:E10) -> 93988624 | F11: =SUBTOTAL(9,F5:F10) -> 5000000 | G11: =SUBTOTAL(9,G5:G10) -> 1.4515974e+09 | H11: =SUBTOTAL(9,H5:H10) -> 6773514.4 | J11: =SUBTOTAL(9,J5:J10) -> 2.0473076e+08 | K11: =SUBTOTAL(9,K5:K10) -> 1.2468666e+09 | N11: Employer Contribution at ESIC
N12: Profession Tax (PTEC)
N13: MLWF Employer Contribution
A14: FY 21-22 | N14: Insurance Charges
A15: Expenses | N15: Printing & Stationery
A16: Particulars | B16: Amount | C16: Land | D16: Project | E16: Expense Type | N16: Professional Fees
A17: Land | B17: =+G5 -> 94026024 | C17: =+B17*$C$145 -> 13261266 | D17: =+B17*$C$146 -> 80764758 | E17: Direct cost (Common) | N17: Repair & Maintenance
A18: Development Expenses (Punawale) | B18: 273000 | C18: =+B18*$C$145 -> 38503.442 | D18: =+B18*$C$146 -> 234496.56 | E18: Direct cost (Common) | N18: Round Off Expense
A19: Bank Charges | B19: 29.5 | C19: =+B19*$C$145 -> 4.1606284 | D19: =+B19*$C$146 -> 25.339372 | E19: Direct cost (Common) | N19: Audit Fees
A20: Total | B20: =SUM(B17:B19) -> 94299053 | C20: =SUM(C17:C19) -> 13299773 | D20: =SUM(D17:D19) -> 80999280 | F20: =+B20-C20-D20 -> 0 | N20: Interest on Late Payment of GST
N21: Bank Charges
N22: Registration and Filing Fees
A23: FY 22-23 | N23: Depreciation - Office Equipments
A24: Expenses | N24: Penalty/Fine/Damages
A25: Particulars | B25: Amount | C25: Land | D25: Project | E25: Expense Type | N25: Deffered Tax - P&L
A26: Opening WIP | B26: =+B20 -> 94299053 | C26: =+C20 -> 13299773 | D26: =+D20 -> 80999280 | N26: Interest On Late Payment of TDS
A27: Land | B27: =+SUM(G6:G8) -> 871011382 | C27: =+B27*$C$145 -> 1.2284592e+08 | D27: =+B27*$C$146 -> 7.4816546e+08 | E27: Direct cost (Common) | N27: Salary - Indirect
A28: Development Expenses (Punawale - S.No. 31) | B28: 11075368 | C28: =+B28*$C$145 -> 1562050.5 | D28: =+B28*$C$146 -> 9513317.5 | E28: Direct cost (Common)
A29: Development Expenses (Punawale - S.No. 32) | B29: 27153746 | C29: =+B29*$C$145 -> 3829716.8 | D29: =+B29*$C$146 -> 23324029 | E29: Direct cost (Common)
A30: Development Expenses (Punawale - S.No 32/3) | B30: 16639975 | C30: =+B30*$C$145 -> 2346873 | D30: =+B30*$C$146 -> 14293102 | E30: Direct cost (Common)
A31: Development Expenses (Punawale-S.No. 32/6) | B31: 8030711 | C31: =+B31*$C$145 -> 1132637.4 | D31: =+B31*$C$146 -> 6898073.6 | E31: Direct cost (Common)
A32: Electrical Work (Punawale-S.No.31) | B32: 2696074 | C32: =+B32*$C$145 -> 380249.56 | D32: =+B32*$C$146 -> 2315824.4 | E32: Direct cost (Common)
A33: Electrical Work (Punawale - S.No. 32) | B33: 6610029 | C33: =+B33*$C$145 -> 932266.92 | D33: =+B33*$C$146 -> 5677762.1 | E33: Direct cost (Common)
A34: Electrical Work (Punawale-S.No. 32/3) | B34: 1664128 | C34: =+B34*$C$145 -> 234705.7 | D34: =+B34*$C$146 -> 1429422.3 | E34: Direct cost (Common)
A35: Electrical Work (Punawale-S.No. 32/6) | B35: 911086 | C35: =+B35*$C$145 -> 128497.98 | D35: =+B35*$C$146 -> 782588.02 | E35: Direct cost (Common)
A36: Fencing Work Expenses (Punawale-S.No. 31) | B36: 772100 | C36: =+B36*$C$145 -> 108895.63 | D36: =+B36*$C$146 -> 663204.37 | E36: Direct cost (Common)
A37: Fencing Work Expenses (Punawale-S.No. 32) | B37: 772100 | C37: =+B37*$C$145 -> 108895.63 | D37: =+B37*$C$146 -> 663204.37 | E37: Direct cost (Common)
A38: Liasoning Expenses (Punawale - S.No. 31) | B38: 4737500 | C38: =+B38*$C$145 -> 668168.71 | D38: =+B38*$C$146 -> 4069331.3 | E38: Direct cost (Common)
A39: Liasoning Expenses (Punawale - S.No. 32) | B39: 16800 | C39: =+B39*$C$145 -> 2369.4426 | D39: =+B39*$C$146 -> 14430.557 | E39: Direct cost (Common)
... A47: Professional Expenses (Punawale -S.No. 32/6) | B47: 14992 | C47: =+B47*$C$145 -> 2114.4454 | D47: =+B47*$C$146 -> 12877.555 | E47: Direct cost (Common)
A48: Total | B48: =SUM(B26:B47) -> 1.0469266e+09 | C48: =SUM(C26:C47) -> 1.476567e+08 | D48: =SUM(D26:D47) -> 8.9926994e+08 | F48: =+B48-C48-D48 -> 0
...

Sheet Notes
A1: Note-1B
A2: Reserves and Surplus
A3: Particulars | B3: HO | D3: Construction Division | F3: Total
B4: =F4 -> Figures as at the end of 31.03.2026 | C4: Figures as at the end of 31.03.2025 | D4: =F4 -> Figures as at the end of 31.03.2026 | E4: Figures as at the end of 31.03.2025 | F4: Figures as at the end of 31.03.2026 | G4: Figures as at the end of 31.03.2025
A6: Profit and Loss A/c
A7: Opening Balance | B7: =+C10 -> -30616.78 | C7: 0 | D7: =-'TB_31.03.2026 (Links)'!E67-'TB_31.03.2026 (Links)'!E66+30617 -> -83426.27 | E7: =-'TB_31.03.2026 (Links)'!H67 -> -2890.55 | F7: =B7+D7 -> -114043.05 | G7: =C7+E7 -> -2890.55
A8: Add :- Surplus / (Deficit) in Statement of Profit and Loss | B8: 0 | C8: =PL!F47 -> -30616.78 | D8: =PL!I40 -> 87914644 | E8: =PL!H47 -> -80535.659 | F8: =B8+D8 -> 87914644 | G8: =C8+E8 -> -111152.44
A10: Grand Total | B10: =SUM(B7:B8) -> -30616.78 | C10: =SUM(C7:C8) -> -30616.78 | D10: =SUM(D7:D8) -> 87831217 | E10: =SUM(E7:E8) -> -83426.209 | F10: =SUM(F7:F8) -> 87800601 | G10: =SUM(G7:G8) -> -114042.99
A12: Note-2
A13: Long-Term Borrowings
A14: Particulars | B14: HO | D14: Construction Division | F14: Total
B15: =B25 -> Figures as at the end of 31.03.2026 | C15: =C25 -> Figures as at the end of 31.03.2025 | D15: =D25 -> Figures as at the end of 31.03.2026 | E15: =E25 -> Figures as at the end of 31.03.2025 | F15: =F25 -> Figures as at the end of 31.03.2026 | G15: =G25 -> Figures as at the end of 31.03.2025
A17: ='TB_31.03.2026 (Links)'!D72 -> Aditya Birla Capital Loan- 935318 | B17: 0 | C17: 0 | D17: =-'TB_31.03.2026 (Links)'!H72-'TB_31.03.2026 (Links)'!M193 -> 3.853325e+08 | E17: 0 | F17: =B17+D17 -> 3.853325e+08 | G17: =C17+E17 -> 0
A18: (Secured against Unsold Units and Land of sapphire 3 project ,developers share )
A19: Grand Total | B19: =SUM(B16:B18) -> 0 | C19: =SUM(C16:C18) -> 0 | D19: =SUM(D16:D18) -> 3.853325e+08 | E19: =SUM(E16:E18) -> 0 | F19: =SUM(F16:F18) -> 3.853325e+08 | G19: =SUM(G16:G18) -> 0
A22: Note-3
A23: Short Term Borrowings
A24: Particulars | B24: HO | D24: Construction Division | F24: Total
B25: =B4 -> Figures as at the end of 31.03.2026 | C25: =C4 -> Figures as at the end of 31.03.2025 | D25: =D4 -> Figures as at the end of 31.03.2026 | E25: =E4 -> Figures as at the end of 31.03.2025 | F25: =F4 -> Figures as at the end of 31.03.2026 | G25: =G4 -> Figures as at the end of 31.03.2025
A27: Bank Overdraft
A28: HDFC-99919917012022-Expenses A/c | B28: 0 | C28: 0 | D28: =-SUM('TB_31.03.2026 (Links)'!H33:H35) -> 27962349 | E28: 0 | F28: =B28+D28 -> 27962349 | G28: =C28+E28 -> 0
A29: (Secured Against Fixed Deposit)
A31: Loans and Advances From Related Parties
A33: Loan from Directors & Relatives (Unsecured & considered good)
A34: Rajesh Goyal | B34: -15550000 | C34: 84450000 | D34: =-'TB_31.03.2026 (Links)'!H70+0.16 -> 2.0563452e+08 | E34: =-'TB_31.03.2026 (Links)'!E70 -> 172634520 | F34: =B34+D34 -> 1.9008452e+08 | G34: =C34+E34 -> 257084520
A35: Vineet Goyal | B35: 152050000 | C35: 327900000 | D35: =-'TB_31.03.2026 (Links)'!H71 -> 49381956 | E35: =-'TB_31.03.2026 (Links)'!E71 -> -218300000 | F35: =B35+D35 -> 201431956 | G35: =C35+E35 -> 109600000
A36: Krishnakumar Goyal | B36: 0 | C36: 55150000 | D36: =-'TB_31.03.2026 (Links)'!H69 -> 121358000 | E36: =-'TB_31.03.2026 (Links)'!E69 -> 29758000 | F36: =B36+D36 -> 121358000 | G36: =C36+E36 -> 84908000
A37: Rehaan Vineet Goyal | B37: 15400000 | C37: 15400000 | D37: 0 | E37: 0 | F37: =B37+D37 -> 15400000 | G37: =C37+E37 -> 15400000
A38: Saesha Goyal | B38: 17000000 | C38: 0 | D38: 0 | E38: 0 | F38: =B38+D38 -> 17000000 | G38: =C38+E38 -> 0
A39: Sheetal Manoj Gupta | B39: 44350000 | C39: 38900000 | D39: 0 | E39: 0 | F39: =B39+D39 -> 44350000 | G39: =C39+E39 -> 38900000
A40: Shilpa Sachin Garg | B40: 45010000 | C40: 30310000 | D40: 0 | E40: 0 | F40: =B40+D40 -> 45010000 | G40: =C40+E40 -> 30310000
A42: Grand Total | B42: =SUM(B26:B41) -> 258260000 | C42: =SUM(C26:C41) -> 552110000 | D42: =SUM(D26:D41) -> 4.0433683e+08 | E42: =SUM(E26:E41) -> -15907480 | F42: =SUM(F26:F41) -> 6.6259683e+08 | G42: =SUM(G26:G41) -> 536202520
A45: Note-5
A46: Other Current Liabilities
A47: Particulars | B47: HO | D47: Construction Division | F47: Total
B48: =B4 -> Figures as at the end of 31.03.2026 | C48: =C4 -> Figures as at the end of 31.03.2025 | D48: =D4 -> Figures as at the end of 31.03.2026 | E48: =E4 -> Figures as at the end of 31.03.2025 | F48: =F4 -> Figures as at the end of 31.03.2026 | G48: =G4 -> Figures as at the end of 31.03.2025
L49: =30532486+1876474-293010 -> 32115950 | N49: =30532486+1876474 -> 32408960
A50: Contractual Deposit Received From Customer | B50: 0 | C50: 0 | D50: =-Customer!I17+-'TB_31.03.2026 (Links)'!H111 -> 1.3634267e+09 | E50: =-Customer!F17+-Customer!F18 -> 1.369242e+09 | F50: =B50+D50 -> 1.3634267e+09 | G50: =C50+E50 -> 1.369242e+09
A52: Branch/Division
A53: Interbranch Transaction | B53: -3.7320444e+08 | C53: =-911972112.13-6566277 -> -9.1853839e+08 | D53: =-'TB_31.03.2026 (Links)'!H59 -> 3.6663816e+08 | E53: =-'TB_31.03.2026 (Links)'!E59 -> 9.1197211e+08 | F53: =B53+D53 -> -6566277 | G53: =C53+E53 -> -6566277
...

Sheet ESC
A1: Moonstone Realinfra Private Limited
A2: CIN :- U45201PN2022PTC207521
A3: A 102 ICC TRADE TOWER 403/A SENAPATI BAPAT ROAD PUNE , MH 411016
A4: NOTES ANNEXED TO AND FORMING PART OF THE BALANCE SHEET AS ON 31ST March 2026
A6: Note 1A
A7: Share Capital
A8: Particulars | B8: Figures as at the end of current reporting Period 31-03-2026 | D8: Figures as at the end of current reporting Period 31-03-2025
B9: Number of shares | C9: Amount | D9: Number of shares | E9: Amount
A10: (a) Authorised
A11: 50,000 Equity shares of Rs.10/- each with voting rights | B11: 50000 | C11: =+B11*10 -> 500000 | D11: 50000 | E11: =+D11*10 -> 500000
A13: (b) Issued, Subscribed and Paid up
A14: At the Beginning of the year
A15: 10,000 Equity shares of Rs.10/- each with voting rights | B15: 10000 | C15: =+B15*10 -> 100000 | D15: 10000 | E15: =+D15*10 -> 100000
A16: Issued During the Year | B16: 0 | C16: 0 | D16: 0 | E16: 0
A17: Shares bought back during the year | B17: 0 | C17: 0 | D17: 0 | E17: 0
A18: At the End of the Year 10,000 Equity Shares of Rs.10 Each with voting Rights | B18: =SUM(B15:B16) -> 10000 | C18: =-'TB_31.03.2026 (Links)'!H65 -> 100000 | D18: =SUM(D15:D16) -> 10000 | E18: =SUM(E15:E16) -> 100000
A21: Shares in the company held by its holding company or its ultimate holding company including shares held by or by subsidiaries or associates of the holding company or the ultimate holding company
A22: Particulars | B22: Figures as at the end of current reporting Period 31-03-2026 | D22: Figures as at the end of current reporting Period 31-03-2025
B23: Number of shares | C23: Amount | D23: Number of shares | E23: Amount
A25: Shares held by Holding Company
A26: Intofinity Promotors Private Limited | B26: 9800 | C26: =+B26*10 -> 98000 | D26: 9800 | E26: =+D26*10 -> 98000
A29: List of Shareholders holding more than 5% share capital
A30: Particulars | B30: Figures as at the end of current reporting Period 31-03-2026 | D30: Figures as at the end of current reporting Period 31-03-2025
B31: Number of shares | C31: % of total shares | D31: Number of shares | E31: % of total shares
A33: Intofinity Promotors Private Limited | B33: 9800 | C33: 98 | D33: 9800 | E33: 98
A34: Total | B34: =SUM(B33:B33) -> 9800 | C34: =SUM(C33:C33) -> 98 | D34: =SUM(D33:D33) -> 9800 | E34: =SUM(E33:E33) -> 98
A36: NOTE 1A. Shares held by Promoter's
A37: For Current Reporting Period
A38: Promotor's Name | B38: No of shares | C38: % of total shares | D38: % Change during the year
A39: Intofinity Promotors Private Limited | B39: 9800 | C39: 98 | D39: 0
A41: Total | B41: =SUM(B39) -> 9800 | C41: =SUM(C39) -> 98
A43: For Previous reporting Period
A44: Promotor's Name | B44: No of shares | C44: % of total shares | D44: % Change during the year
A45: Intofinity Promotors Private Limited | B45: 9800 | C45: 98 | D45: 0
A47: Total | B47: =SUM(B45:B46) -> 9800 | C47: =SUM(C45:C46) -> 98
A49: In terms of our report attached.
A50: For Bhandari S A A J & Associates | C50: For, Kothari Cars Private Limited
A51: Chartered Accountants
A52: FRN : 108155W
A55: CA. Pravin B. Bhandari | C55: Rajendra B. Kothari | E55: Ashish R. Kothari | G55: Ashish R. Kothari
...

Sheet Note-4
A2: Note 4 | J2: Vendor Account: Name 1 | K2: MSME Status | L2: Sum of Company Code Currency Value | M2: Count of Count of Outstanding More than 3 Years | N2: Count of Count of Outstanding since 2 to 3 Year | O2: Sum of Sum of Outstanding since 1 to 2 Year | P2: Sum of Sum of Outstanding less Than 1 Year | Q2: MSME | R2: Other
A3: Trade Payables | J3: 360 Realtors LLP | K3: Other | L3: 99945.8 | M3: 0 | N3: 0 | O3: 0 | P3: 99945.8 | R3: =P3 -> 99945.8
J4: LANDROOF & CO | K4: Other | L4: 2716.02 | M4: 0 | N4: 0 | O4: 0 | P4: 2716.02 | R4: =P4 -> 2716.02
A5: Figures as at the end of 31.03.2026 | J5: Mahesh Tulashiram Golawar | K5: Other | L5: 19600 | M5: 0 | N5: 0 | O5: 0 | P5: 19600 | R5: =P5 -> 19600
A6: Particulars | B6: Outstanding for following periods from due date of payment | F6: Total | J6: Prajkta Rajendra Dhanokar | K6: Other | L6: 9800 | M6: 0 | N6: 0 | O6: 9800 | P6: 0 | R6: =P6 -> 0
B7: Less than 1 Year | C7: 1-2 Years | D7: 2-3 Years | E7: More than 3 Years | J7: PropTiger Marketing Services Pvt. L | K7: Other | L7: 1364447.5 | M7: 0 | N7: 0 | O7: 0 | P7: 1364447.5 | R7: =P7 -> 1364447.5
A8: MSME | B8: =Q18 -> 16500 | C8: 0 | D8: 0 | E8: 0 | F8: =SUM(B8:E8) -> 16500 | J8: RENUKA ENTERPRISES | K8: Other | L8: 19800 | M8: 0 | N8: 0 | O8: 19800 | P8: 0 | R8: =P8 -> 0
A9: Others | B9: =R18 -> 1.8497197e+08 | C9: =O18 -> 1.5369573e+08 | D9: 0 | E9: 0 | F9: =SUM(B9:E9) -> 3.386677e+08 | J9: SAI ENTERPRISES | K9: Other | L9: 98954 | M9: 0 | N9: 0 | O9: 0 | P9: 98954 | R9: =P9 -> 98954
A10: Dispute dues-MSME | B10: 0 | C10: 0 | D10: 0 | E10: 0 | F10: =SUM(B10:E10) -> 0 | J10: THANISH CONSTRUCTION LLP | K10: Other | L10: 3.3475597e+08 | M10: 0 | N10: 0 | O10: 1.5366613e+08 | P10: 1.8108984e+08 | R10: =P10 -> 1.8108984e+08
A11: Dispute dues others | B11: 0 | C11: 0 | D11: 0 | E11: 0 | F11: =SUM(B11:E11) -> 0 | J11: BHANDARI SAAJ & ASSOCIATES | K11: Other | L11: 0 | M11: 0 | N11: 0 | O11: 0 | P11: 0 | R11: =P11 -> 0
A12: Total | B12: =SUM(B8:B11) -> 1.8498847e+08 | C12: =SUM(C8:C11) -> 1.5369573e+08 | D12: =SUM(D8:D11) -> 0 | E12: =SUM(E8:E11) -> 0 | F12: =SUM(F8:F11) -> 3.386842e+08 | J12: FAST FACILITY SERVICES | K12: Other | L12: 145019.34 | M12: 0 | N12: 0 | O12: 0 | P12: 145019.34 | R12: =P12 -> 145019.34
J13: NIKISHA CONSULTANCY SERVICES | K13: Other | L13: 7350 | M13: 0 | N13: 0 | O13: 0 | P13: 7350 | R13: =P13 -> 7350
A14: Figures as at the end of 31.03.2025 | J14: Sadguru Enterprises | K14: MSME | L14: 16500 | M14: 0 | N14: 0 | O14: 0 | P14: 16500 | Q14: =P14 -> 16500
A15: Particulars | B15: Outstanding for following periods from due date of payment | F15: Total | J15: VK DESIGN AND PROJECTS PRIVATE LIMI | K15: Other | L15: 2093040 | M15: 0 | N15: 0 | O15: 0 | P15: 2093040 | R15: =P15 -> 2093040
B16: Less than 1 Year | C16: 1-2 Years | D16: 2-3 Years | E16: More than 3 Years | J16: TEJAS SUDAM THAKUR PATIL | K16: Other | L16: 27828 | M16: 0 | N16: 0 | O16: 0 | P16: 27828 | R16: =P16 -> 27828
A17: MSME | B17: 543846.53 | C17: 0 | D17: 0 | E17: 0 | F17: =SUM(B17:E17) -> 543846.53 | J17: MANOJ KUMAR VARMA | K17: Other | L17: 23230 | P17: =L17 -> 23230 | R17: =P17 -> 23230
A18: Others | B18: 5.7107583e+08 | C18: 0 | D18: 0 | E18: 0 | F18: =SUM(B18:E18) -> 5.7107583e+08 | J18: Total | L18: =SUM(L3:L17) -> 3.386842e+08 | O18: =SUM(O3:O17) -> 1.5369573e+08 | P18: =SUM(P3:P17) -> 1.8498847e+08 | Q18: =SUM(Q3:Q17) -> 16500 | R18: =SUM(R3:R17) -> 1.8497197e+08
A19: Dispute dues-MSME | B19: 0 | C19: 0 | D19: 0 | E19: 0 | F19: =SUM(B19:E19) -> 0
A20: Dispute dues Others | B20: 0 | C20: 0 | D20: 0 | E20: 0 | F20: =SUM(B20:E20) -> 0
A21: Total | B21: =SUM(B17:B20) -> 5.7161968e+08 | C21: =SUM(C17:C20) -> 0 | D21: =SUM(D17:D20) -> 0 | E21: =SUM(E17:E20) -> 0 | F21: =SUM(F17:F20) -> 5.7161968e+08

Sheet Dep & DTA DTL
B4: Note-7
B5: Property, Plant and Equipment
B7: Block of Assets | C7: Name of Assets | D7: Opening WDV | E7: Date of Acquisition/ Put to Use | F7: Residual Value | G7: Useful Life | H7: No. Days Used till Last Period | I7: Balance Life | J7: No. Days Used in Current Year | K7: Depreciation Rate | L7: Depreciation Amount | M7: Closing WDV
B9: Plant & Machinery | C9: Office Equipment | D9: =SUM('TB_31.03.2026 (Links)'!E5:E6) -> 32341.13 | E9: 45415 | F9: =D9*0.05 -> 1617.0565 | G9: 5 | H9: 0 | I9: =(5*365-J9)/365 -> 4 | J9: 365 | K9: =1-((F9/D9)^(1/G9)) -> 0.45071973 | L9: =D9*K9/365*J9-1 -> 14575.785 | M9: =D9-L9 -> 17765.345
B12: Grand Total | D12: =SUM(D9:D11) -> 32341.13 | F12: =SUM(F9:F11) -> 1617.0565 | L12: =SUM(L9:L11) -> 14575.785 | M12: =SUM(M9:M11) -> 17765.345
B17: Note 8
B18: Deferred Tax Assets (Net)
B20: Block of Asset | C20: Name of Asset | D20: Rate | E20: Opening WDV | F20: Addition | H20: Deletion | J20: Depreciation | K20: Closing WDV
F21: More Than 180 Days | G21: Less Than 180 Days | H21: More Than 180 Days | I21: Less Than 180 Days
B23: Plant & Machinery | C23: Office Equipment | D23: 0.15 | E23: 46589.35 | F23: 0 | G23: 0 | H23: 0 | I23: 0 | J23: =(E23*D23)+(F23*D23)+(G23*D23/2) -> 6988.4025 | K23: =SUM(E23:G23)-SUM(H23:J23) -> 39600.948
B25: Grand Total | E25: =SUM(E23) -> 46589.35 | F25: =SUM(F23) -> 0 | G25: =SUM(G23) -> 0 | H25: =SUM(H23) -> 0 | I25: 0 | J25: =SUM(J23) -> 6988.4025 | K25: =SUM(K23) -> 39600.948
B28: Deffered Tax Assets/Deffered Tax Liability
B30: Particular | C30: Amount
B31: Depreciation as per books | C31: =L9 -> 14575.785
B32: Depreciation as per Income Tax | C32: =J23 -> 6988.4025
B33: Deductiable Temporary Difference | C33: =C31-C32 -> 7587.3828
B34: Tax Rate | C34: 0.25168
B35: Deffered Tax Assets should be created | C35: =C33*C34 -> 1909.5925
B36: Opening DTA | C36: 3586
B37: Closing DTA | C37: =C35+C36 -> 5495.5925

Sheet Customer Reco details
A1: Customer details
AG2: =SUBTOTAL(9,AG4:AG948) -> -1.3634267e+09
A3: Sr.No. | B3: Project Name | C3: Flat No | D3: Tower | E3: Unit No | F3: Unit Type | G3: Saleable Area Sq.Ft | H3: RERA Carpet Area Sq.Ft | I3: Total Carpet Area Sq.Ft | J3: Title | K3: Customer Code | L3: Customer Name | M3: Customer Pan | N3: Registration No | O3: Registration Date | P3: Total Agreement Value | Q3: Booking Status | R3: Opening - Maintenance | S3: Opening - SDR | T3: Opening Receipt | U3: Total Opening (As per TB 31-3-25) | V3: Receipts Including GST | W3: Receipt- TDS | X3: Due-Maintenance | Y3: Receipt - Maintenance | Z3: Payment-SDR | AA3: Receipt-SDR | AB3: Due-Interest (Including GST) | AC3: GST | AD3: Payment Including GST (Refund) | AE3: Due Booking Cancellation (Including GST) | AF3: Sales | AG3: Closing Balance (As per TB 31-3-26) | AH3: Remark | AI3: As per GST payable Ledger of books 25-26 | AJ3: Net receipt against Flat (Basic) | AL3: Diff
A4: 1 | B4: KOHINOOR UPTOWN AVENUE | C4: Tower 8-608 | D4: Tower 8 | E4: 608 | F4: 2BHK | G4: 1012 | H4: 653.59 | I4: 723.02 | J4: Mr. | K4: 2002502 | L4: ABHIJEET BALASAHEB LONDHE | M4: AVQPL7206G | N4: 2134/2024 | O4: 45441 | P4: 5683644 | Q4: SOLD | R4: 0 | S4: 0 | T4: -1697949.3 | U4: =SUM(R4:T4) -> -1697949.3 | V4: 0 | W4: 0 | X4: 0 | Y4: 0 | Z4: 0 | AA4: 0 | AB4: 0 | AC4: -7142.9 | AD4: 0 | AG4: =SUM(U4:AF4) -> -1705092.2 | AI4: 7142.9 | AJ4: =SUM(U4:AE4) -> -1705092.2 | AL4: =+AC4+AI4 -> 0 | AO4: 2002502 | AP4: 20412001
A5: =A4+1 -> 2 | B5: KOHINOOR UPTOWN AVENUE | C5: Tower 1-1107 | D5: Tower 1 | E5: 1107 | F5: 2BHK | G5: 1114 | H5: 683.3 | I5: 795.57 | J5: Mr. | K5: 2020808 | L5: ABHIJEET KUSURKAR | M5: BCSPK1165K | P5: 6928571 | Q5: CANCELLED | R5: 0 | S5: 0 | T5: -75000 | U5: =SUM(R5:T5) -> -75000 | V5: 75000 | W5: 0 | X5: 0 | Y5: 0 | Z5: 0 | AA5: 0 | AB5: 0 | AC5: 0 | AD5: 0 | AG5: =SUM(U5:AF5) -> 0 | AI5: 0 | AJ5: =SUM(U5:AE5) -> 0 | AL5: =+AC5-AI5 -> 0 | AO5: 2020808 | AP5: 20412016
A6: =A5+1 -> 3 | B6: KOHINOOR UPTOWN AVENUE | C6: Tower 7-901 | D6: Tower 7 | E6: 901 | F6: 2BHK | G6: 1012 | H6: 653.59 | I6: 723.02 | J6: Mr. | K6: 2002404 | L6: ABHIJEET NAMDEV PATIL | M6: BVNPP0532M | N6: 2627/2024 | O6: 45462 | P6: 5698827 | Q6: SOLD | R6: 0 | S6: 0 | T6: -1707263.6 | U6: =SUM(R6:T6) -> -1707263.6 | V6: 0 | W6: 0 | X6: 0 | Y6: 0 | Z6: 0 | AA6: 0 | AB6: 0 | AC6: -2380.9 | AD6: 0 | AG6: =SUM(U6:AF6) -> -1709644.5 | AI6: 2380.9 | AJ6: =SUM(U6:AE6) -> -1709644.5 | AL6: =+AC6+AI6 -> 0 | AO6: 2002404 | AP6: 20412009
A7: =A6+1 -> 4 | B7: KOHINOOR UPTOWN AVENUE | C7: Tower 4-1703 | D7: Tower 4 | E7: 1703 | F7: 3BHK | G7: 1787 | H7: 1138.51 | I7: 1276.29 | J7: Mr. | K7: 2018875 | L7: ABHIJEET PRAKASH SAMANT | M7: AZCPS1564J | N7: 4689/2024 | O7: 45629 | P7: 14080286 | Q7: SOLD | R7: 0 | S7: 0 | T7: -4322636.6 | U7: =SUM(R7:T7) -> -4322636.6 | V7: -95238 | W7: 0 | X7: 0 | Y7: 0 | Z7: 0 | AA7: 0 | AB7: 0 | AC7: 0 | AD7: 0 | AG7: =SUM(U7:AF7) -> -4417874.6 | AI7: 0 | AJ7: =SUM(U7:AE7) -> -4417874.6 | AL7: =+AC7-AI7 -> 0 | AO7: 2018875 | AP7: 20412003
A8: =A7+1 -> 5 | B8: KOHINOOR UPTOWN AVENUE | C8: Tower 2-1201 | D8: Tower 2 | E8: 1201 | F8: 2BHK | G8: 1012 | H8: 653.59 | I8: 723.02 | J8: Ms. | K8: 2020347 | L8: ABHIJIT ANIL SHRUNGARE | M8: ETMPS6757M | P8: 6134762 | Q8: SOLD | R8: 0 | S8: 0 | T8: -650905 | U8: =SUM(R8:T8) -> -650905 | V8: 0 | W8: 0 | X8: 0 | Y8: 0 | Z8: 0 | AA8: 0 | AB8: 0 | AC8: 0 | AD8: 0 | AG8: =SUM(U8:AF8) -> -650905 | AI8: 0 | AJ8: =SUM(U8:AE8) -> -650905 | AL8: =+AC8-AI8 -> 0 | AO8: 2020347 | AP8: 20412005
A9: =A8+1 -> 6 | B9: KOHINOOR UPTOWN AVENUE | C9: Tower 8-1805 | D9: Tower 8 | E9: 1805 | F9: Row House | G9: 1265 | H9: 813.33 | I9: 903.31 | J9: Mr. | K9: 2002464 | L9: ABHIJIT ARUNRAO KHANDAR | M9: BJYPK7780D | N9: 2904/2024 | O9: 45475 | P9: 7142857 | Q9: CANCELLED | R9: 0 | S9: 0 | T9: -1834244 | U9: =SUM(R9:T9) -> -1834244 | V9: 1834244 | W9: 0 | X9: 0 | Y9: 0 | Z9: 0 | AA9: 0 | AB9: 0 | AC9: 0 | AD9: 0 | AG9: =SUM(U9:AF9) -> 0 | AI9: 0 | AJ9: =SUM(U9:AE9) -> 0 | AL9: =+AC9-AI9 -> 0 | AO9: 2002464 | AP9: 20412007
A10: =A9+1 -> 7 | B10: KOHINOOR UPTOWN AVENUE | C10: Tower 2-301 | D10: Tower 2 | E10: 301 | F10: 2BHK | G10: 1012 | H10: 653.59 | I10: 723.02 | J10: Mr. | K10: 2019572 | L10: ABHIJIT ARUNRAO KULKARNI | M10: BNQPK0310M | P10: 6044643 | Q10: CANCELLED | R10: 0 | S10: 0 | T10: -758947 | U10: =SUM(R10:T10) -> -758947 | V10: 770544 | W10: 0 | X10: 0 | Y10: 0 | Z10: 0 | AA10: 0 | AB10: 0 | AC10: -23194 | AD10: 0 | AG10: =SUM(U10:AF10) -> -11597 | AI10: 23194 | AJ10: =SUM(U10:AE10) -> -11597 | AL10: =+AC10+AI10 -> 0 | AO10: 2019572 | AP10: 20412010
A11: =A10+1 -> 8 | B11: KOHINOOR UPTOWN AVENUE | C11: Tower 1-701 | D11: Tower 1 | E11: 701 | F11: 2BHK | G11: 1012 | H11: 653.59 | I11: 723.02 | J11: Mr. | K11: 2018482 | L11: ABHIJIT LAXMAN NALAWADE | M11: BGVPN4676D | P11: 6437429 | Q11: CANCELLED | R11: 0 | S11: 0 | T11: -778281 | U11: =SUM(R11:T11) -> -778281 | V11: 778281 | W11: 0 | X11: 0 | Y11: 0 | Z11: 0 | AA11: 0 | AB11: 0 | AC11: 0 | AD11: 0 | AG11: =SUM(U11:AF11) -> 0 | AI11: 0 | AJ11: =SUM(U11:AE11) -> 0 | AL11: =+AC11-AI11 -> 0 | AO11: 2018482 | AP11: 20412008
A12: =A11+1 -> 9 | B12: KOHINOOR UPTOWN AVENUE | C12: Tower 2-1902 | D12: Tower 2 | E12: 1902 | F12: 2BHK | G12: 1114 | H12: 683.3 | I12: 795.57 | J12: Mr. | K12: 2021311 | L12: ABHIJIT LAXMAN NALAWADE | M12: BGVPN4676D | P12: 7205357 | Q12: CANCELLED | R12: 0 | S12: 0 | T12: 0 | U12: =SUM(R12:T12) -> 0 | V12: 0 | W12: 0 | X12: 0 | Y12: 0 | Z12: 0 | AA12: 0 | AB12: 0 | AC12: 0 | AD12: 0 | AG12: =SUM(U12:AF12) -> 0 | AI12: 0 | AJ12: =SUM(U12:AE12) -> 0 | AL12: =+AC12-AI12 -> 0 | AO12: 2021311 | AP12: 20412002
A13: =A12+1 -> 10 | B13: KOHINOOR UPTOWN AVENUE | C13: Tower 6-1202 | D13: Tower 6 | E13: 1202 | F13: 2BHK | G13: 1114 | H13: 683.3 | I13: 795.57 | J13: Mr. | K13: 2017884 | L13: ABHIJIT PRAKASHRAO DATIR | M13: BYIPD4430L | N13: 2842/2024 | O13: 45470 | P13: 6401714 | Q13: SOLD | R13: 0 | S13: 0 | T13: -2083531.3 | U13: =SUM(R13:T13) -> -2083531.3 | V13: 0 | W13: 0 | X13: 0 | Y13: 0 | Z13: 0 | AA13: 0 | AB13: 0 | AC13: 0 | AD13: 0 | AG13: =SUM(U13:AF13) -> -2083531.3 | AI13: 0 | AJ13: =SUM(U13:AE13) -> -2083531.3 | AL13: =+AC13-AI13 -> 0 | AO13: 2017884 | AP13: 20412017
A14: =A13+1 -> 11 | B14: KOHINOOR UPTOWN AVENUE | C14: Tower 6-308 | D14: Tower 6 | E14: 308 | F14: 2BHK | G14: 1012 | H14: 653.59 | I14: 723.02 | J14: Mr. | K14: 2017703 | L14: ABHIJIT SHANKARRAO SALUNKHE | M14: IKFPS3114A | N14: 2550/2024 | O14: 45456 | P14: 5758858 | Q14: SOLD | R14: 0 | S14: 0 | T14: -1785245.1 | U14: =SUM(R14:T14) -> -1785245.1 | V14: 0 | W14: 0 | X14: 0 | Y14: 0 | Z14: 0 | AA14: 0 | AB14: 0 | AC14: 0 | AD14: 0 | AG14: =SUM(U14:AF14) -> -1785245.1 | AI14: 0 | AJ14: =SUM(U14:AE14) -> -1785245.1 | AL14: =+AC14-AI14 -> 0 | AO14: 2017703 | AP14: 20412004
A15: =A14+1 -> 12 | B15: KOHINOOR UPTOWN AVENUE | C15: Tower 7-1007 | D15: Tower 7 | E15: 1007 | F15: 2BHK | G15: 1114 | H15: 683.3 | I15: 795.57 | J15: Mr. | K15: 2018907 | L15: ABHIMANYU MARUTI GHARGINE | M15: ABQPG9733K | N15: 3349/2024 | O15: 45509 | P15: 6304075 | Q15: SOLD | R15: 0 | S15: 0 | T15: -484221.61 | U15: =SUM(R15:T15) -> -484221.61 | V15: -1407000 | W15: 0 | X15: 0 | Y15: 0 | Z15: 0 | AA15: 0 | AB15: 0 | AC15: -16667 | AD15: 0 | AG15: =SUM(U15:AF15) -> -1907888.6 | AI15: 16667 | AJ15: =SUM(U15:AE15) -> -1907888.6 | AL15: =+AC15+AI15 -> 0 | AO15: 2018907 | AP15: 20412006
A16: =A15+1 -> 13 | B16: KOHINOOR UPTOWN AVENUE | C16: Tower 1-707 | D16: Tower 1 | E16: 707 | F16: 2BHK | G16: 1114 | H16: 683.3 | I16: 795.57 | J16: Mr. | K16: 2018363 | L16: ABHISHEK CHANDRAKANT SURYAWANSHI | M16: LVJPS2992E | P16: 7155788 | Q16: CANCELLED | R16: 0 | S16: 0 | T16: -140253 | U16: =SUM(R16:T16) -> -140253 | V16: 151000 | W16: 0 | X16: 0 | Y16: 0 | Z16: 0 | AA16: 0 | AB16: 0 | AC16: -21493.57 | AD16: 0 | AG16: =SUM(U16:AF16) -> -10746.57 | AI16: 21494 | AJ16: =SUM(U16:AE16) -> -10746.57 | AL16: =+AC16+AI16 -> 0.43 | AO16: 2018363
A17: =A16+1 -> 14 | B17: KOHINOOR UPTOWN AVENUE | C17: Tower 7-1601 | D17: Tower 7 | E17: 1601 | F17: 2BHK | G17: 1012 | H17: 653.59 | I17: 723.02 | J17: Mr. | K17: 2021019 | L17: ABHISHEK CHOUHAN | M17: AJNPC6908P | N17: 2061/2025 | O17: 45737 | P17: 6151714 | Q17: SOLD | R17: 0 | S17: 0 | T17: -1845514.3 | U17: =SUM(R17:T17) -> -1845514.3 | V17: -61517.14 | W17: 0 | X17: 0 | Y17: 0 | Z17: 0 | AA17: 0 | AB17: 0 | AC17: 0 | AD17: 0 | AG17: =SUM(U17:AF17) -> -1907031.4 | AI17: 0 | AJ17: =SUM(U17:AE17) -> -1907031.4 | AL17: =+AC17-AI17 -> 0 | AO17: 2021019
A18: =A17+1 -> 15 | B18: KOHINOOR UPTOWN AVENUE | C18: Tower 8-1001 | D18: Tower 8 | E18: 1001 | F18: 2BHK | G18: 1012 | H18: 653.59 | I18: 723.02 | J18: Mr. | K18: 2002410 | L18: ABHISHEK DILIP BONDARDE | M18: BLDPB6997C | N18: 1713/2024 | O18: 45429 | P18: 5698827 | Q18: SOLD | R18: 0 | S18: 0 | T18: -1759492.7 | U18: =SUM(R18:T18) -> -1759492.7 | V18: -200000 | W18: 0 | X18: 0 | Y18: 0 | Z18: 0 | AA18: 0 | AB18: 0 | AC18: -7143 | AD18: 0 | AG18: =SUM(U18:AF18) -> -1966635.7 | AI18: 7143 | AJ18: =SUM(U18:AE18) -> -1966635.7 | AL18: =+AC18+AI18 -> 0 | AO18: 2002410
A19: =A18+1 -> 16 | B19: KOHINOOR UPTOWN AVENUE | C19: Tower 6-2208 | D19: Tower 6 | E19: 2208 | F19: 2BHK | G19: 1012 | H19: 653.59 | I19: 723.02 | J19: Mr. | K19: 2015482 | L19: ABHISHEK MODI | M19: BMOPM2291L | N19: 3036/2024 | O19: 45483 | P19: 5910666 | Q19: SOLD | R19: 0 | S19: 0 | T19: -1833196 | U19: =SUM(R19:T19) -> -1833196 | V19: 50000 | W19: 0 | X19: 0 | Y19: 0 | Z19: 0 | AA19: 0 | AB19: 0 | AC19: 0 | AD19: 0 | AG19: =SUM(U19:AF19) -> -1783196 | AI19: 0 | AJ19: =SUM(U19:AE19) -> -1783196 | AL19: =+AC19-AI19 -> 0 | AO19: 2015482
A20: =A19+1 -> 17 | B20: KOHINOOR UPTOWN AVENUE | C20: Tower 3-1407 | D20: Tower 3 | E20: 1407 | F20: 2BHK | G20: 1114 | H20: 683.3 | I20: 795.57 | J20: Mr. | K20: 2001892 | L20: ABHISHEK PRAVINKUMAR KODULE | M20: EPNPK9324H | N20: 2542/2024 | O20: 45456 | P20: 6339238 | Q20: SOLD | R20: 0 | S20: 0 | T20: -1844627.4 | U20: =SUM(R20:T20) -> -1844627.4 | V20: -50000 | W20: 0 | X20: 0 | Y20: 0 | Z20: 0 | AA20: 0 | AB20: 0 | AC20: 0 | AD20: 0 | AG20: =SUM(U20:AF20) -> -1894627.4 | AI20: 0 | AJ20: =SUM(U20:AE20) -> -1894627.4 | AL20: =+AC20-AI20 -> 0 | AO20: 2001892
A21: =A20+1 -> 18 | B21: KOHINOOR UPTOWN AVENUE | C21: Tower 3-1902 | D21: Tower 3 | E21: 1902 | F21: 2BHK | G21: 1114 | H21: 683.3 | I21: 795.57 | J21: Mr. | K21: 2002189 | L21: ABHISHEK RAJENDRA HINGE | M21: AXIPH5032N | N21: 2003/2024 | O21: 45434 | P21: 6337489 | Q21: SOLD | R21: 0 | S21: 0 | T21: -1711383.7 | U21: =SUM(R21:T21) -> -1711383.7 | V21: -182718 | W21: 0 | X21: 0 | Y21: 0 | Z21: 0 | AA21: 0 | AB21: 0 | AC21: 0 | AD21: 0 | AG21: =SUM(U21:AF21) -> -1894101.7 | AI21: 0 | AJ21: =SUM(U21:AE21) -> -1894101.7 | AL21: =+AC21+AI21 -> 0 | AO21: 2002189
A22: =A21+1 -> 19 | B22: KOHINOOR UPTOWN AVENUE | C22: Tower 3-1205 | D22: Tower 3 | E22: 1205 | F22: 3BHK | G22: 1498 | H22: 954.87 | I22: 1069.73 | J22: Mr. | K22: 2022124 | L22: ABHISHEK SONI | M22: BSPPS9925N | N22: 2888/2024 | O22: 45474 | P22: 8812477 | Q22: SOLD | R22: 0 | S22: 0 | T22: -2731866.6 | U22: =SUM(R22:T22) -> -2731866.6 | V22: 0 | W22: 0 | X22: 0 | Y22: 0 | Z22: 0 | AA22: 0 | AB22: 0 | AC22: 0 | AD22: 0 | AG22: =SUM(U22:AF22) -> -2731866.6 | AI22: 0 | AJ22: =SUM(U22:AE22) -> -2731866.6 | AL22: =+AC22-AI22 -> 0 | AO22: 2022124
A23: =A22+1 -> 20 | B23: KOHINOOR UPTOWN AVENUE | C23: Tower 4-306 | D23: Tower 4 | E23: 306 | F23: 3BHK | G23: 1787 | H23: 1138.51 | I23: 1276.29 | J23: Mr. | K23: 2002244 | L23: ABHISHEK UPADHYAY | M23: ABLPU5450C | N23: 2508/2024 | O23: 45455 | P23: 10776761 | Q23: SOLD | R23: 0 | S23: 0 | T23: -3308464.6 | U23: =SUM(R23:T23) -> -3308464.6 | V23: 0 | W23: 0 | X23: 0 | Y23: 0 | Z23: 0 | AA23: 0 | AB23: 0 | AC23: 0 | AD23: 0 | AG23: =SUM(U23:AF23) -> -3308464.6 | AI23: 0 | AJ23: =SUM(U23:AE23) -> -3308464.6 | AL23: =+AC23-AI23 -> 0 | AO23: 2002244
A24: =A23+1 -> 21 | B24: KOHINOOR UPTOWN AVENUE | C24: Tower 4-901 | D24: Tower 4 | E24: 901 | F24: 3BHK | G24: 1787 | H24: 1138.51 | I24: 1276.29 | J24: Mr. | K24: 2002256 | L24: ABINASH ACHARYA | M24: BKJPA0876Q | N24: 2087/2024 | O24: 45439 | P24: 11269682 | Q24: CANCELLED | R24: 0 | S24: 0 | T24: -2993782.9 | U24: =SUM(R24:T24) -> -2993782.9 | V24: 2958290 | W24: 0 | X24: 0 | Y24: 0 | Z24: 0 | AA24: 0 | AB24: 0 | AC24: 0 | AD24: 0 | AG24: =SUM(U24:AF24) -> -35492.9 | AI24: 0 | AJ24: =SUM(U24:AE24) -> -35492.9 | AL24: =+AC24-AI24 -> 0 | AO24: 2002256
A25: =A24+1 -> 22 | B25: KOHINOOR UPTOWN AVENUE | C25: Tower 8-1104 | D25: Tower 8 | E25: 1104 | F25: 3BHK | G25: 1498 | H25: 954.87 | I25: 1069.73 | J25: Ms. | K25: 2002418 | L25: ABOLI AVINASH PATHAK | M25: ECGPP5376E | N25: 2450/2024 | O25: 45454 | P25: 8492059 | Q25: SOLD | R25: 0 | S25: 0 | T25: -2509727.1 | U25: =SUM(R25:T25) -> -2509727.1 | V25: 0 | W25: 0 | X25: 0 | Y25: 0 | Z25: 0 | AA25: 0 | AB25: 0 | AC25: -25238.6 | AD25: 0 | AG25: =SUM(U25:AF25) -> -2534965.7 | AI25: 25238.6 | AJ25: =SUM(U25:AE25) -> -2534965.7 | AL25: =+AC25+AI25 -> 0 | AO25: 2002418
A26: =A25+1 -> 23 | B26: KOHINOOR UPTOWN AVENUE | C26: Tower 2-1007 | D26: Tower 2 | E26: 1007 | F26: 2BHK | G26: 1114 | H26: 683.3 | I26: 795.57 | J26: Mr. | K26: 2021515 | L26: ADITYA ABHAY GAIKWAD | M26: DFWPG8744D | P26: 7026762 | Q26: CANCELLED | R26: 0 | S26: 0 | T26: -75000 | U26: =SUM(R26:T26) -> -75000 | V26: 75000 | W26: 0 | X26: 0 | Y26: 0 | Z26: 0 | AA26: 0 | AB26: 0 | AC26: 0 | AD26: 0 | AG26: =SUM(U26:AF26) -> 0 | AI26: 0 | AJ26: =SUM(U26:AE26) -> 0 | AL26: =+AC26-AI26 -> 0 | AO26: 2021515
A27: =A26+1 -> 24 | B27: KOHINOOR UPTOWN AVENUE | C27: Tower 7-804 | D27: Tower 7 | E27: 804 | F27: 2.5BHK | G27: 1265 | H27: 813.33 | I27: 903.31 | J27: Mr. | K27: 2002399 | L27: ADITYA AJAY BIDKAR | M27: CTQPB9937G | N27: 1838/2024 | O27: 45428 | P27: 7164190 | Q27: SOLD | R27: 0 | S27: 0 | T27: -2216374 | U27: =SUM(R27:T27) -> -2216374 | V27: 0 | W27: 0 | X27: 0 | Y27: 0 | Z27: 0 | AA27: 0 | AB27: 0 | AC27: 0 | AD27: 0 | AG27: =SUM(U27:AF27) -> -2216374 | AI27: 0 | AJ27: =SUM(U27:AE27) -> -2216374 | AL27: =+AC27+AI27 -> 0 | AO27: 2002399
A28: =A27+1 -> 25 | B28: KOHINOOR UPTOWN AVENUE | C28: Tower 3-607 | D28: Tower 3 | E28: 607 | F28: 2BHK | G28: 1114 | H28: 683.3 | I28: 795.57 | J28: Mr. | K28: 2002220 | L28: ADITYA DEEPAK FUKE | M28: ACOPF6786C | N28: 2050/2024 | O28: 45440 | P28: 6287368 | Q28: SOLD | R28: 0 | S28: 0 | T28: -1879068.5 | U28: =SUM(R28:T28) -> -1879068.5 | V28: 0 | W28: 0 | X28: 0 | Y28: 0 | Z28: 0 | AA28: 0 | AB28: 0 | AC28: -7142 | AD28: 0 | AG28: =SUM(U28:AF28) -> -1886210.5 | AI28: 7142 | AJ28: =SUM(U28:AE28) -> -1886210.5 | AL28: =+AC28+AI28 -> 0 | AO28: 2002220
A29: =A28+1 -> 26 | B29: KOHINOOR UPTOWN AVENUE | C29: Tower 3-1001 | D29: Tower 3 | E29: 1001 | F29: 2BHK | G29: 1012 | H29: 653.59 | I29: 723.02 | J29: Mr. | K29: 2001869 | L29: ADITYA GAJANAN VEDPATHAK | M29: AYIPV8704G | N29: 1976/2024 | O29: 45435 | P29: 5698827 | Q29: SOLD | R29: 0 | S29: 0 | T29: -1759492.6 | U29: =SUM(R29:T29) -> -1759492.6 | V29: 0 | W29: 0 | X29: 0 | Y29: 0 | Z29: 0 | AA29: 0 | AB29: 0 | AC29: -7142 | AD29: 0 | AG29: =SUM(U29:AF29) -> -1766634.6 | AI29: 7142 | AJ29: =SUM(U29:AE29) -> -1766634.6 | AL29: =+AC29+AI29 -> 0 | AO29: 2001869
A30: =A29+1 -> 27 | B30: KOHINOOR UPTOWN AVENUE | C30: Tower 3-1203 | D30: Tower 3 | E30: 1203 | F30: 3BHK | G30: 1375 | H30: 876.73 | I30: 982.22 | J30: Mr. | K30: 2015843 | L30: ADITYA PATIL | M30: CNPPP3018R | N30: 2661/2024 | O30: 45463 | P30: 7678571 | Q30: SOLD | R30: 0 | S30: 0 | T30: -2303573.1 | U30: =SUM(R30:T30) -> -2303573.1 | V30: 0 | W30: 0 | X30: 0 | Y30: 0 | Z30: 0 | AA30: 0 | AB30: 0 | AC30: 0 | AD30: 0 | AG30: =SUM(U30:AF30) -> -2303573.1 | AI30: 0 | AJ30: =SUM(U30:AE30) -> -2303573.1 | AL30: =+AC30-AI30 -> 0 | AO30: 2015843
A31: =A30+1 -> 28 | B31: KOHINOOR UPTOWN AVENUE | C31: Tower 8-1904 | D31: Tower 8 | E31: 1904 | F31: 3BHK | G31: 1498 | H31: 954.87 | I31: 1069.73 | J31: Mrs. | K31: 2019424 | L31: AHIRE SEEMA SAHEBRAO | M31: AHHPA9667M | N31: 4088/2024 | O31: 45560 | P31: 8946381 | Q31: SOLD | R31: 0 | S31: 0 | T31: -2673378.1 | U31: =SUM(R31:T31) -> -2673378.1 | V31: 0 | W31: 0 | X31: 0 | Y31: 0 | Z31: 0 | AA31: 0 | AB31: 0 | AC31: 0 | AD31: 0 | AG31: =SUM(U31:AF31) -> -2673378.1 | AI31: 0 | AJ31: =SUM(U31:AE31) -> -2673378.1 | AL31: =+AC31-AI31 -> 0 | AO31: 2019424
A32: =A31+1 -> 29 | B32: KOHINOOR UPTOWN AVENUE | C32: Tower 3-1006 | D32: Tower 3 | E32: 1006 | F32: 3BHK | G32: 1375 | H32: 876.73 | I32: 982.22 | J32: Mr. | K32: 2001872 | L32: AJAY ANANDRAO BHANDARE | M32: NJHMK6793D | N32: 2868/2024 | O32: 45471 | P32: 7741048 | Q32: SOLD | R32: 0 | S32: 0 | T32: -2293825.8 | U32: =SUM(R32:T32) -> -2293825.8 | V32: 0 | W32: 0 | X32: 0 | Y32: 0 | Z32: 0 | AA32: 0 | AB32: 0 | AC32: 0 | AD32: 0 | AG32: =SUM(U32:AF32) -> -2293825.8 | AI32: 0 | AJ32: =SUM(U32:AE32) -> -2293825.8 | AL32: =+AC32-AI32 -> 0 | AO32: 2001872
A33: =A32+1 -> 30 | B33: KOHINOOR UPTOWN AVENUE | C33: Tower 8-1304 | D33: Tower 8 | E33: 1304 | F33: 2.5BHK | G33: 1265 | H33: 813.33 | I33: 903.31 | J33: Mr. | K33: 2002430 | L33: AJAY KUMAR SAH | M33: EPTPS7020J | N33: 3028/2024 | O33: 45483 | P33: 7160667 | Q33: SOLD | R33: 0 | S33: 0 | T33: -2219804 | U33: =SUM(R33:T33) -> -2219804 | V33: 0 | W33: 0 | X33: 0 | Y33: 0 | Z33: 0 | AA33: 0 | AB33: 0 | AC33: 0 | AD33: 0 | AG33: =SUM(U33:AF33) -> -2219804 | AI33: 0 | AJ33: =SUM(U33:AE33) -> -2219804 | AL33: =+AC33-AI33 -> 0 | AO33: 2002430
A34: =A33+1 -> 31 | B34: KOHINOOR UPTOWN AVENUE | C34: Tower 4-304 | D34: Tower 4 | E34: 304 | F34: 3BHK | G34: 1787 | H34: 1138.51 | I34: 1276.29 | J34: Mr. | K34: 2002242 | L34: AJAY SINGH | M34: AETPT3769G | N34: 2357/2024 | O34: 45448 | P34: 10866000 | Q34: SOLD | R34: 0 | S34: 0 | T34: -3368460 | U34: =SUM(R34:T34) -> -3368460 | V34: 0 | W34: 0 | X34: 0 | Y34: 0 | Z34: 0 | AA34: 0 | AB34: 0 | AC34: 0 | AD34: 0 | AG34: =SUM(U34:AF34) -> -3368460 | AI34: 0 | AJ34: =SUM(U34:AE34) -> -3368460 | AL34: =+AC34-AI34 -> 0 | AO34: 2002242
A35: =A34+1 -> 32 | B35: KOHINOOR UPTOWN AVENUE | C35: Tower 3-1005 | D35: Tower 3 | E35: 1005 | F35: 3BHK | G35: 1498 | H35: 954.87 | I35: 1069.73 | J35: Mrs. | K35: 2001871 | L35: AJITA PRASAD DESHPANDE | M35: AIPPU3226P | N35: 1905/2024 | O35: 45429 | P35: 8581345 | Q35: SOLD | R35: 0 | S35: 0 | T35: -2552951.8 | U35: =SUM(R35:T35) -> -2552951.8 | V35: 0 | W35: 0 | X35: 0 | Y35: 0 | Z35: 0 | AA35: 0 | AB35: 0 | AC35: -21454 | AD35: 0 | AG35: =SUM(U35:AF35) -> -2574405.8 | AI35: 21454 | AJ35: =SUM(U35:AE35) -> -2574405.8 | AL35: =+AC35+AI35 -> 0 | AO35: 2001871
A36: =A35+1 -> 33 | B36: KOHINOOR UPTOWN AVENUE | C36: Tower 8-408 | D36: Tower 8 | E36: 408 | F36: 2BHK | G36: 1012 | H36: 653.59 | I36: 723.02 | J36: Mr. | K36: 2002494 | L36: AKASH DEBASHISH CHATTERJI | M36: BDMPC9577Q | N36: 1826/2024 | O36: 45434 | P36: 5668460 | Q36: SOLD | R36: 0 | S36: 0 | T36: -1725222.7 | U36: =SUM(R36:T36) -> -1725222.7 | V36: 0 | W36: 0 | X36: 0 | Y36: 0 | Z36: 0 | AA36: 0 | AB36: 0 | AC36: -31999 | AD36: 0 | AG36: =SUM(U36:AF36) -> -1757221.7 | AI36: 31999 | AJ36: =SUM(U36:AE36) -> -1757221.7 | AL36: =+AC36+AI36 -> 0 | AO36: 2002494
A37: =A36+1 -> 34 | B37: KOHINOOR UPTOWN AVENUE | C37: Tower 4-902 | D37: Tower 4 | E37: 902 | F37: 3BHK | G37: 1787 | H37: 1138.51 | I37: 1276.29 | J37: Mr. | K37: 2019333 | L37: AKASH RAJENDRA TAWADE | M37: BJSPT4107R | N37: 3027/2024 | O37: 45483 | P37: 11580286 | Q37: SOLD | R37: 0 | S37: 0 | T37: -3383554.6 | U37: =SUM(R37:T37) -> -3383554.6 | V37: -50000 | W37: 0 | X37: 0 | Y37: 0 | Z37: 0 | AA37: 0 | AB37: 0 | AC37: -6596 | AD37: 0 | AG37: =SUM(U37:AF37) -> -3440150.6 | AI37: 6596 | AJ37: =SUM(U37:AE37) -> -3440150.6 | AL37: =+AC37+AI37 -> 0 | AO37: 2019333
A38: =A37+1 -> 35 | B38: KOHINOOR UPTOWN AVENUE | C38: Tower 1-2108 | D38: Tower 1 | E38: 2108 | F38: 2BHK | G38: 1012 | H38: 653.59 | I38: 723.02 | J38: Mr. | K38: 2017977 | L38: Akash Ramesh Naktode | M38: ATNPN5524E | P38: 6151714 | Q38: SOLD | R38: 0 | S38: 0 | T38: -1100478 | U38: =SUM(R38:T38) -> -1100478 | V38: 0 | W38: 0 | X38: 0 | Y38: 0 | Z38: 0 | AA38: 0 | AB38: 0 | AC38: 0 | AD38: 0 | AG38: =SUM(U38:AF38) -> -1100478 | AI38: 0 | AJ38: =SUM(U38:AE38) -> -1100478 | AL38: =+AC38-AI38 -> 0 | AO38: 2017977
A39: =A38+1 -> 36 | B39: KOHINOOR UPTOWN AVENUE | C39: Tower 6-702 | D39: Tower 6 | E39: 702 | F39: 2BHK | G39: 1114 | H39: 683.3 | I39: 795.57 | J39: Mr. | K39: 2002275 | L39: AKASH SAMBHE | M39: GFDPE7974P | N39: 2091/2024 | O39: 45439 | P39: 6401714 | Q39: SOLD | R39: 0 | S39: 0 | T39: -1984531.4 | U39: =SUM(R39:T39) -> -1984531.4 | V39: 0 | W39: 0 | X39: 0 | Y39: 0 | Z39: 0 | AA39: 0 | AB39: 0 | AC39: 0 | AD39: 0 | AG39: =SUM(U39:AF39) -> -1984531.4 | AI39: 0 | AJ39: =SUM(U39:AE39) -> -1984531.4 | AL39: =+AC39-AI39 -> 0 | AO39: 2002275
A40: =A39+1 -> 37 | B40: KOHINOOR UPTOWN AVENUE | C40: Tower 6-905 | D40: Tower 6 | E40: 905 | F40: 2BHK | G40: 1498 | H40: 954.87 | I40: 1069.73 | J40: Mr. | K40: 2018838 | L40: AKASH SHANTARAM DOKE | M40: CUNPD7096Q | N40: 4694/2024 | O40: 45629 | P40: 9491048 | Q40: SOLD | R40: 0 | S40: 0 | T40: -2847314.3 | U40: =SUM(R40:T40) -> -2847314.3 | V40: -264000 | W40: 0 | X40: 0 | Y40: 0 | Z40: 0 | AA40: 0 | AB40: 0 | AC40: 0 | AD40: 0 | AG40: =SUM(U40:AF40) -> -3111314.3 | AI40: 0 | AJ40: =SUM(U40:AE40) -> -3111314.3 | AL40: =+AC40-AI40 -> 0 | AO40: 2018838
...

Sheet Customer
B2: Company Code | C2: G/L Account | D2: BS type | E2: G/L Acct Long Text | F2: Balance Carryforward | G2: Debit Blnce of Reportng Period | H2: Credit Balance Reporting Per. | I2: Accumulated Balance
B3: 1900 | C3: 10500001 | D3: Assets | E3: Domestic Customers - Basic & Infra | F3: 8.3513225e+08 | G3: 82317594 | H3: 53683313 | I3: 8.6376653e+08
B4: 1900 | C4: 10500002 | D4: Assets | E4: Domestic Customers - GST | F4: 45177027 | G4: 3583960.8 | H4: 1842689.6 | I4: 46918298
B5: 1900 | C5: 10500003 | D5: Assets | E5: Domestic Customers - SDR | F5: -22777476 | G5: 22831301 | H5: 24576201 | I5: -24522376
B6: 1900 | C6: 10500009 | D6: Assets | E6: Domestic Customers | F6: 2.611514e+08 | G6: 2.4050037e+08 | H6: 3.3088872e+08 | I6: 1.7076304e+08
B7: 1900 | C7: 10500100 | D7: Assets | E7: Customer-Others | F7: 0 | G7: 2319592.6 | H7: 2319592.6 | I7: 0
B8: 1900 | C8: 20710001 | D8: Liabilities | E8: Customer - Advance Taken | F8: -1.1499424e+09 | G8: 1.1884096e+08 | H8: 48909539 | I8: -1.080011e+09
B9: 1900 | C9: 20710003 | D9: Liabilities | E9: Customer - Tax on Advance | F9: -56136700 | G9: 8725600.4 | H9: 3068424.9 | I9: -50479525
B10: 1900 | C10: 20710011 | D10: Liabilities | E10: Customer - EOI / Token | F10: -8849234.8 | G10: 57432076 | H10: 57104448 | I10: -8521606.7
B11: 1900 | C11: 20710013 | D11: Liabilities | E11: Customer - Tax on EOI | F11: 2358044.8 | G11: 1238084.8 | H11: 2411164.9 | I11: 1184964.7
B12: 1900 | C12: 20710015 | D12: Liabilities | E12: Customer - SDR Advance | F12: 13298862 | G12: 58336400 | H12: 50087718 | I12: 21547544
B13: 1900 | C13: 20710016 | D13: Liabilities | E13: Customer - Maintenance Advance | F13: -600 | G13: 0 | H13: 0 | I13: -600
B14: 1900 | C14: 20710019 | D14: Liabilities | E14: Customer - Refund EOI & Advance | F14: 79000 | G14: 1.0977475e+08 | H14: 1.2127158e+08 | I14: -11417835
... B16: 1900 | C16: 20710101 | D16: Liabilities | E16: Customer - Due | F16: -1.2854945e+09 | G16: 1.1376662e+08 | H16: 1.1941114e+08 | I16: -1.291139e+09
F17: =SUM(F3:F16) -> -1.3653798e+09 | I17: =SUM(I3:I16) -> -1.3619116e+09
B18: 1900 | C18: 20490001 | D18: Liabilities | E18: Customer Suspense | F18: -3862156.7 | G18: 12417810 | H18: 10070752 | I18: -1515098.7
F19: =F17+F18 -> -1.369242e+09
F21: 1.369242e+09
F22: =F19+F21 -> 0

Sheet SAP Cross Check
B2: Amounts as per SAP | D2: BS PL Amounts | E2: Difference | F2: Reasons | H2: Final Difference
A4: Row Labels | B4: Sum of Accumulated Balance | F4: There are 3 branch balances in TB: - Interbranch Transaction Cr 71,20,22,472 (SAP Assets) (Our BS Liab) - Branch Ho-Liablities Cr 72,86,681 (SAP Liab) (Our BS Liab) - Branch-Ho-Assets Dr 72,56,064 (SAP Assets) (Our BS Liab) So, Difference is coming due to change in classification, SAP Assets > Our BS Liability | G4: DTA entry yet to be passed in SAP
A5: Assets | B5: 3.2045034e+09 | D5: =BS!F32 -> 2.9976385e+09 | E5: =B5-D5 -> 2.0686486e+08 | F5: =Notes!D53+Notes!D55 -> 3.6663816e+08 | G5: ='Dep & DTA DTL'!C35 -> 1909.5925 | H5: =SUM(E5:G5) -> 5.7350493e+08
A6: Expenses | B6: 2.8473134e+08 | D6: =SUM(PL!G15:G21)+PL!G37 -> 2.4584805e+08 | E6: =B6-D6 -> 38883289 | G6: =-'Dep & DTA DTL'!C35 -> -1909.5925 | H6: =SUM(E6:G6) -> 38881380
A7: Income | B7: -3265123.6 | D7: =PL!G12 -> 3.6617165e+08 | E7: =B7+D7 -> 362906530 | H7: =SUM(E7:G7) -> 362906530
A8: Liabilities | B8: -3.4859696e+09 | D8: =D5-PL!G47 -> 2.8773149e+09 | E8: =B8+D8 -> -6.0865468e+08 | F8: =-Notes!D53-Notes!D55 -> -3.6663816e+08 | H8: =SUM(E8:G8) -> -9.7529284e+08
A9: (blank) | B9: 0
A10: Grand Total | B10: 0

Sheet Raw TB_26.04.2026 (SAP Paste)
A4: Copy Paste SAP TB here under the same headings | F4: =+SUBTOTAL(9,F6:F207) -> -1.3176543e+09 | G4: =+SUBTOTAL(9,G6:G207) -> 0 | H4: =+SUBTOTAL(9,H6:H207) -> 8.0161269e+08 | I4: =+SUBTOTAL(9,I6:I207) -> 2.2711824e+08 | J4: =+SUBTOTAL(9,J6:J207) -> -7.4315988e+08 | L4: If error means Ledger Heading not present in TB (Input)
